<mujoco model="R2V2">
  <compiler angle="radian" meshdir="meshes_shell/"/>
  <default>
    <equality solref='0.001 2'/>
    <joint damping="0.01" armature="0.01" frictionloss="0.01" limited="true"/>
  </default>

  <asset>
    <mesh name="base_link" file="base_link.STL"/>
    <mesh name="left_hip_pitch_link" file="left_hip_pitch_link.STL"/>
    <mesh name="left_hip_roll_link" file="left_hip_roll_link.STL"/>
    <mesh name="left_hip_yaw_link" file="left_hip_yaw_link.STL"/>
    <mesh name="left_knee_link" file="left_knee_link.STL"/>
    <mesh name="left_ankle_pitch_link" file="left_ankle_pitch_link.STL"/>
    <mesh name="left_ankle_roll_link" file="left_ankle_roll_link.STL"/>
    <mesh name="right_hip_pitch_link" file="right_hip_pitch_link.STL"/>
    <mesh name="right_hip_roll_link" file="right_hip_roll_link.STL"/>
    <mesh name="right_hip_yaw_link" file="right_hip_yaw_link.STL"/>
    <mesh name="right_knee_link" file="right_knee_link.STL"/>
    <mesh name="right_ankle_pitch_link" file="right_ankle_pitch_link.STL"/>
    <mesh name="right_ankle_roll_link" file="right_ankle_roll_link.STL"/>
    <mesh name="waist_yaw_link" file="waist_yaw_link.STL"/>
    <mesh name="waist_pitch_link" file="waist_pitch_link.STL"/>
    <mesh name="left_shoulder_pitch_link" file="left_shoulder_pitch_link.STL"/>
    <mesh name="left_shoulder_roll_link" file="left_shoulder_roll_link.STL"/>
    <mesh name="left_shoulder_yaw_link" file="left_shoulder_yaw_link.STL"/>
    <mesh name="left_arm_pitch_link" file="left_arm_pitch_link.STL"/>
    <mesh name="left_arm_yaw_link" file="left_arm_yaw_link.STL"/>
    <mesh name="left_hand_pitch_link" file="left_hand_pitch_link.STL"/>
    <mesh name="left_hand_roll_link" file="left_hand_roll_link.STL"/>
    <mesh name="right_shoulder_pitch_link" file="right_shoulder_pitch_link.STL"/>
    <mesh name="right_shoulder_roll_link" file="right_shoulder_roll_link.STL"/>
    <mesh name="right_shoulder_yaw_link" file="right_shoulder_yaw_link.STL"/>
    <mesh name="right_arm_pitch_link" file="right_arm_pitch_link.STL"/>
    <mesh name="right_arm_yaw_link" file="right_arm_yaw_link.STL"/>
    <mesh name="right_hand_pitch_link" file="right_hand_pitch_link.STL"/>
    <mesh name="right_hand_roll_link" file="right_hand_roll_link.STL"/>
    <mesh name="head_yaw_link" file="head_yaw_link.STL"/>
    <mesh name="head_pitch_link" file="head_pitch_link.STL"/>

    <texture type="skybox" builtin="flat" rgb1="0 0 0" rgb2="0 0 0" width="512" height="3072"/>
    <texture type="2d" name="groundplane" builtin="checker" mark="edge" rgb1="0.2 0.3 0.4" rgb2="0.1 0.2 0.3" markrgb="0.8 0.8 0.8" width="300" height="300"/>
    <material name="groundplane" texture="groundplane" texuniform="true" texrepeat="5 5" reflectance="0.2"/>
  </asset>

  <worldbody>
    <light pos="1 0 3.5" dir="0 0 -1" directional="true"/>
    <geom name="floor" size="0 0 0.05" type="plane" material="groundplane"/>
    <body name="base_link" pos="0.0 0.0 0.85">
      <inertial pos="0.0147989 -2.66e-05 0.0415372" quat="0.705209 -0.00101322 -0.00124177 0.708998" mass="4.967" diaginertia="0.00738495 0.00711679 0.00444738"/>
      <joint name="floating_base_joint" type="free"/>
      <site name='imu_in_base' size='0.01' pos='-0.00400350000  -0.00339701234 0.07367500000'/>
      <geom type="mesh" contype="0" conaffinity="0" group="1" density="0" rgba="0.698039 0.698039 0.698039 1" mesh="base_link"/>
      <geom size="0.065 0.05 0.075" pos="0 0 0.03" type="box" rgba="0.698039 0.698039 0.698039 0"/>
      <geom size="0.1 0.05" pos="0 0 0.04" quat="0.707388 0.706825 0 0" type="cylinder" rgba="0.698039 0.698039 0.698039 0"/>
      <body name="left_hip_pitch_link" pos="0 0.1273 0" quat="0.995885 0 -0.0906305 0">
        <inertial pos="-0.0001804 -0.0221744 -0.00050887" quat="0.999781 0.0207166 -1.86318e-05 0.00291545" mass="1.19" diaginertia="0.00263519 0.00181697 0.00158552"/>
        <joint name="left_hip_pitch_joint" pos="0 0 0" axis="0 1 0" range="-1.134 1.3964"/>
        <geom type="mesh" contype="0" conaffinity="0" group="1" density="0" rgba="0.698039 0.698039 0.698039 1" mesh="left_hip_pitch_link"/>
        <geom type="mesh" rgba="0.698039 0.698039 0.698039 1" mesh="left_hip_pitch_link"/>
        <body name="left_hip_roll_link">
          <inertial pos="0.0254272 0.00304569 -0.0714469" quat="0.864259 0.032426 0.088209 0.49419" mass="2.22" diaginertia="0.0136916 0.0132008 0.00455209"/>
          <joint name="left_hip_roll_joint" pos="0 0 0" axis="1 0 0" range="-0.1396 2.44346"/>
          <geom type="mesh" contype="0" conaffinity="0" group="1" density="0" rgba="0.698039 0.698039 0.698039 1" mesh="left_hip_roll_link"/>
          <geom type="mesh" rgba="0.698039 0.698039 0.698039 1" mesh="left_hip_roll_link"/>
          <body name="left_hip_yaw_link" pos="0 0 -0.1725">
            <inertial pos="-0.0110677 0.00018357 -0.0779563" quat="0.695642 0.122908 0.120706 0.697428" mass="2.94" diaginertia="0.0193012 0.0171238 0.00508282"/>
            <joint name="left_hip_yaw_joint" pos="0 0 0" axis="0 0 1" range="-2.79253 2.79253"/>
            <geom type="mesh" contype="0" conaffinity="0" group="1" density="0" rgba="0.698039 0.698039 0.698039 1" mesh="left_hip_yaw_link"/>
            <geom type="mesh" rgba="0.698039 0.698039 0.698039 1" mesh="left_hip_yaw_link"/>
            <body name="left_knee_link" pos="-0.066081 0.021 -0.18756" quat="0.995885 0 0.0906305 0">
              <inertial pos="0.00354423 -0.0182264 -0.193323" quat="0.75431 -0.0133259 0.0203184 0.656069" mass="3.88" diaginertia="0.0467672 0.0463562 0.00408002"/>
              <joint name="left_knee_joint" pos="0 0 0" axis="0 1 0" range="-0.53058 2.50629"/>
              <geom type="mesh" contype="0" conaffinity="0" group="1" density="0" rgba="0.698039 0.698039 0.698039 1" mesh="left_knee_link"/>
              <geom type="mesh" rgba="0.698039 0.698039 0.698039 1" mesh="left_knee_link"/>
              <body name="left_ankle_pitch_link" pos="0 -0.021 -0.405">
                <inertial pos="0 0 0" quat="0 0.707107 0 0.707107" mass="0.0575" diaginertia="1.724e-05 1.506e-05 3.63e-06"/>
                <joint name="left_ankle_pitch_joint" pos="0 0 0" axis="0 1 0" range="-0.872665 0.610865"/>
                <geom type="mesh" contype="0" conaffinity="0" group="1" density="0" rgba="0.752941 0.752941 0.752941 1" mesh="left_ankle_pitch_link"/>
                <geom type="mesh" rgba="0.752941 0.752941 0.752941 1" mesh="left_ankle_pitch_link"/>
                <body name="left_ankle_roll_link">
                  <inertial pos="0.0209017 -0.00031729 -0.04045" quat="0.00165375 0.720525 -0.00098949 0.693427" mass="1.36" diaginertia="0.00676502 0.00603263 0.00120251"/>
                  <joint name="left_ankle_roll_joint" pos="0 0 0" axis="1 0 0" range="-0.349066 0.349066"/>
                  <geom type="mesh" contype="0" conaffinity="0" group="1" density="0" rgba="0.698039 0.698039 0.698039 1" mesh="left_ankle_roll_link"/>
                  <geom size="0.005" pos="-0.07 0.045 -0.05" rgba="0.698039 0.698039 0.698039 1"/>
                  <geom size="0.005" pos="-0.07 -0.045 -0.05" rgba="0.698039 0.698039 0.698039 1"/>
                  <geom size="0.005" pos="0.115 0.045 -0.05" rgba="0.698039 0.698039 0.698039 1"/>
                  <geom size="0.005" pos="0.115 -0.045 -0.05" rgba="0.698039 0.698039 0.698039 1"/>
                  <geom size="0.008" pos="-0.06 0.03 0" rgba="0.698039 0.698039 0.698039 1"/>
                  <geom size="0.008" pos="-0.06 -0.03 0" rgba="0.698039 0.698039 0.698039 1"/>
                </body>
              </body>
            </body>
          </body>
        </body>
      </body>
      <body name="right_hip_pitch_link" pos="0 -0.1273 0" quat="0.995885 0 -0.0906305 0">
        <inertial pos="-0.00037071 0.0220567 -0.00050635" quat="0.993908 0.110048 -0.000448774 -0.00599696" mass="1.19" diaginertia="0.00263959 0.00183967 0.00157921"/>
        <joint name="right_hip_pitch_joint" pos="0 0 0" axis="0 1 0" range="-1.134 1.3964"/>
        <geom type="mesh" contype="0" conaffinity="0" group="1" density="0" rgba="0.698039 0.698039 0.698039 1" mesh="right_hip_pitch_link"/>
        <geom size="0.05 0.025" quat="0.707388 0 0.706825 0" type="cylinder" rgba="0.698039 0.698039 0.698039 1"/>
        <body name="right_hip_roll_link">
          <inertial pos="0.0253968 -0.00306927 -0.0714668" quat="0.493596 0.0882444 0.0325133 0.864592" mass="2.22" diaginertia="0.0136916 0.0131976 0.00455478"/>
          <joint name="right_hip_roll_joint" pos="0 0 0" axis="1 0 0" range="-2.44346 0.1396"/>
          <geom type="mesh" contype="0" conaffinity="0" group="1" density="0" rgba="0.698039 0.698039 0.698039 1" mesh="right_hip_roll_link"/>
          <geom type="mesh" rgba="0.698039 0.698039 0.698039 1" mesh="right_hip_roll_link"/>
          <body name="right_hip_yaw_link" pos="0 0 -0.1725">
            <inertial pos="-0.0109242 -0.00013538 -0.0776774" quat="0.697793 0.120624 0.122242 0.695407" mass="2.93" diaginertia="0.0191428 0.0169826 0.00506112"/>
            <joint name="right_hip_yaw_joint" pos="0 0 0" axis="0 0 1" range="-2.79253 2.79253"/>
            <geom type="mesh" contype="0" conaffinity="0" group="1" density="0" rgba="0.698039 0.698039 0.698039 1" mesh="right_hip_yaw_link"/>
            <geom type="mesh" rgba="0.698039 0.698039 0.698039 1" mesh="right_hip_yaw_link"/>
            <body name="right_knee_link" pos="-0.066081 -0.021 -0.18756" quat="0.995885 0 0.0906305 0">
              <inertial pos="0.00354555 0.0182425 -0.193211" quat="0.657306 0.0203843 -0.0135073 0.753227" mass="3.89" diaginertia="0.0468177 0.0464043 0.00408663"/>
              <joint name="right_knee_joint" pos="0 0 0" axis="0 1 0" range="-0.53058 2.50629"/>
              <geom type="mesh" contype="0" conaffinity="0" group="1" density="0" rgba="0.698039 0.698039 0.698039 1" mesh="right_knee_link"/>
              <geom type="mesh" rgba="0.698039 0.698039 0.698039 1" mesh="right_knee_link"/>
              <body name="right_ankle_pitch_link" pos="0 0.021 -0.405">
                <inertial pos="0 0 0" quat="0 0.707107 0 0.707107" mass="0.0575" diaginertia="1.724e-05 1.506e-05 3.63e-06"/>
                <joint name="right_ankle_pitch_joint" pos="0 0 0" axis="0 1 0" range="-0.872665 0.610865"/>
                <geom type="mesh" contype="0" conaffinity="0" group="1" density="0" rgba="0.752941 0.752941 0.752941 1" mesh="right_ankle_pitch_link"/>
                <geom type="mesh" rgba="0.752941 0.752941 0.752941 1" mesh="right_ankle_pitch_link"/>
                <body name="right_ankle_roll_link">
                  <inertial pos="0.0205799 0.00028918 -0.0404497" quat="-0.00145664 0.720675 0.00100923 0.69327" mass="1.36" diaginertia="0.00675536 0.00602291 0.00120228"/>
                  <joint name="right_ankle_roll_joint" pos="0 0 0" axis="1 0 0" range="-0.349066 0.349066"/>
                  <geom type="mesh" contype="0" conaffinity="0" group="1" density="0" rgba="0.698039 0.698039 0.698039 1" mesh="right_ankle_roll_link"/>
                  <geom size="0.005" pos="-0.07 0.045 -0.05" rgba="0.698039 0.698039 0.698039 1"/>
                  <geom size="0.005" pos="-0.07 -0.045 -0.05" rgba="0.698039 0.698039 0.698039 1"/>
                  <geom size="0.005" pos="0.115 0.045 -0.05" rgba="0.698039 0.698039 0.698039 1"/>
                  <geom size="0.005" pos="0.115 -0.045 -0.05" rgba="0.698039 0.698039 0.698039 1"/>
                  <geom size="0.008" pos="-0.06 0.03 0" rgba="0.698039 0.698039 0.698039 1"/>
                  <geom size="0.008" pos="-0.06 -0.03 0" rgba="0.698039 0.698039 0.698039 1"/>
                </body>
              </body>
            </body>
          </body>
        </body>
      </body>
      <body name="waist_yaw_link" pos="0 0 0.14275">
        <inertial pos="0.00021189 -0.00871956 0.0449228" quat="0.44512 0.546224 0.404338 0.58311" mass="1.46" diaginertia="0.00311564 0.00223919 0.00202075"/>
        <joint name="waist_yaw_joint" pos="0 0 0" axis="0 0 1" range="-2.00713 2.00713"/>
        <geom type="mesh" contype="0" conaffinity="0" group="1" density="0" rgba="0.698039 0.698039 0.698039 1" mesh="waist_yaw_link"/>
        <geom type="mesh" rgba="0.698039 0.698039 0.698039 1" mesh="waist_yaw_link"/>
        <body name="waist_pitch_link" pos="0 0 0.0615">
          <inertial pos="0.00364193 -0.00194534 0.203126" quat="0.999928 0.00543176 0.010708 0.000332945" mass="14.9672" diaginertia="0.250995 0.212947 0.118166"/>
          <joint name="waist_pitch_joint" pos="0 0 0" axis="0 1 0" range="-0.523599 0.523599"/>
          <geom type="mesh" contype="0" conaffinity="0" group="1" density="0" rgba="0.698039 0.698039 0.698039 1" mesh="waist_pitch_link"/>
          <geom type="mesh" rgba="0.698039 0.698039 0.698039 1" mesh="waist_pitch_link"/>
          <body name="left_shoulder_pitch_link" pos="0 0.14042 0.3608" quat="0.996195 0.0871543 0 0">
            <inertial pos="0.00027984 0.0288454 0.00139413" quat="0.986319 0.164285 0.0136411 0.000169413" mass="0.657" diaginertia="0.000537574 0.000455957 0.000369319"/>
            <joint name="left_shoulder_pitch_joint" pos="0 0 0" axis="0 1 0" range="-3.08923 2.67035"/>
            <geom type="mesh" contype="0" conaffinity="0" group="1" density="0" rgba="0.698039 0.698039 0.698039 1" mesh="left_shoulder_pitch_link"/>
            <!-- <geom type="mesh" rgba="0.698039 0.698039 0.698039 1" mesh="left_shoulder_pitch_link"/> -->
            <geom size="0.02 0.015" pos="0 0.055 0" quat="0.707282 0 0.706931 0" type="cylinder" rgba="0.698039 0.698039 0.698039 1"/>
            <body name="left_shoulder_roll_link" pos="0.03575 0.050671 -0.008" quat="0.996195 -0.0871543 0 0">
              <inertial pos="-0.023668 0.0040135 -0.0303708" quat="0.649172 0.262894 0.172202 0.692682" mass="0.21" diaginertia="0.00034671 0.000332911 0.000199168"/>
              <joint name="left_shoulder_roll_joint" pos="0 0 0" axis="1 0 0" range="-0.0872665 2.25147"/>
              <geom type="mesh" contype="0" conaffinity="0" group="1" density="0" rgba="0.698039 0.698039 0.698039 1" mesh="left_shoulder_roll_link"/>
              <!-- <geom type="mesh" rgba="0.698039 0.698039 0.698039 1" mesh="left_shoulder_roll_link"/> -->
              <body name="left_shoulder_yaw_link" pos="-0.03575 0.005 -0.0575">
                <inertial pos="-0.00514794 -0.00182092 -0.0983308" quat="0.959442 -0.0378047 -0.0557707 0.273735" mass="1.336" diaginertia="0.00407994 0.00399483 0.0010757"/>
                <joint name="left_shoulder_yaw_joint" pos="0 0 0" axis="0 0 1" range="-2.61799 2.61799"/>
                <geom type="mesh" contype="0" conaffinity="0" group="1" density="0" rgba="0.698039 0.698039 0.698039 1" mesh="left_shoulder_yaw_link"/>
                <!-- <geom type="mesh" rgba="0.698039 0.698039 0.698039 1" mesh="left_shoulder_yaw_link"/> -->
                <geom size="0.005 0.05" pos="0 0.02 -0.1" type="cylinder" rgba="0.698039 0.698039 0.698039 1"/>
                <body name="left_arm_pitch_link" pos="0.015711 0.03172 -0.144">
                  <inertial pos="0.0697252 -0.0270972 -0.0165953" quat="0.269253 0.774535 0.0812363 0.566568" mass="0.658" diaginertia="0.000863164 0.000855857 0.000538739"/>
                  <joint name="left_arm_pitch_joint" pos="0 0 0" axis="0 1 0" range="-2.61799 2.61799"/>
                  <geom type="mesh" contype="0" conaffinity="0" group="1" density="0" rgba="0.698039 0.698039 0.698039 1" mesh="left_arm_pitch_link"/>
                  <!-- <geom type="mesh" rgba="0.698039 0.698039 0.698039 1" mesh="left_arm_pitch_link"/> -->
                  <geom size="0.03 0.025" pos="0.07 -0.03 -0.015" quat="0.707282 0 -0.706931 0" type="cylinder" rgba="0.698039 0.698039 0.698039 1"/>
                  <body name="left_arm_yaw_link" pos="0.111 -0.03125 -0.018">
                    <inertial pos="0.025938 -0.0110748 -1.629e-05" quat="0.227855 0.669704 -0.225287 0.669944" mass="0.14" diaginertia="0.00022855 0.000216325 0.000131375"/>
                    <joint name="left_arm_yaw_joint" pos="0 0 0" axis="1 0 0" range="-1.97222 1.97222"/>
                    <geom type="mesh" contype="0" conaffinity="0" group="1" density="0" rgba="0.698039 0.698039 0.698039 1" mesh="left_arm_yaw_link"/>
                    <geom type="mesh" rgba="0.698039 0.698039 0.698039 1" mesh="left_arm_yaw_link"/>
                    <body name="left_hand_pitch_link" pos="0.051 -0.03175 0">
                      <inertial pos="0.0388115 0.0305894 -0.00274469" quat="0.453599 0.518487 0.54906 0.473236" mass="0.941" diaginertia="0.0014239 0.00138016 0.000759439"/>
                      <joint name="left_hand_pitch_joint" pos="0 0 0" axis="0 1 0" range="-1.97222 1.97222"/>
                      <geom type="mesh" contype="0" conaffinity="0" group="1" density="0" rgba="0.698039 0.698039 0.698039 1" mesh="left_hand_pitch_link"/>
                      <geom type="mesh" rgba="0.698039 0.698039 0.698039 1" mesh="left_hand_pitch_link"/>
                      <body name="left_hand_roll_link" pos="0.068 0.03175 0.03175">
                        <inertial pos="0.0951687 -1.6e-06 -0.0300965" quat="0.468409 0.529661 0.529786 0.46838" mass="0.125" diaginertia="0.000910631 0.000865381 0.000216191"/>
                        <joint name="left_hand_roll_joint" pos="0 0 0" axis="0 0 1" range="-1.0472 1.0472"/>
                        <geom type="mesh" contype="0" conaffinity="0" group="1" density="0" rgba="0.698039 0.698039 0.698039 1" mesh="left_hand_roll_link"/>
                        <geom type="mesh" rgba="0.698039 0.698039 0.698039 1" mesh="left_hand_roll_link"/>
                        <geom size="5e-07 5e-07 5e-07" pos="0.0735 0 -0.03175" quat="0.499998 -0.5 0.500002 -0.5" type="box" contype="0" conaffinity="0" group="1" density="0" rgba="0.698039 0.698039 0.698039 1"/>
                        <geom size="5e-07 5e-07 5e-07" pos="0.0735 0 -0.03175" quat="0.499998 -0.5 0.500002 -0.5" type="box" rgba="0.698039 0.698039 0.698039 1"/>
                      </body>
                    </body>
                  </body>
                </body>
              </body>
            </body>
          </body>
          <body name="right_shoulder_pitch_link" pos="0 -0.14042 0.3608" quat="0.996195 -0.0871543 0 0">
            <inertial pos="0.00027988 -0.0288454 0.0013941" quat="0.986317 -0.164295 0.0136316 -0.000125357" mass="0.656" diaginertia="0.000536753 0.000455264 0.000368763"/>
            <joint name="right_shoulder_pitch_joint" pos="0 0 0" axis="0 1 0" range="-3.08923 2.67035"/>
            <geom type="mesh" contype="0" conaffinity="0" group="1" density="0" rgba="0.792157 0.819608 0.933333 1" mesh="right_shoulder_pitch_link"/>
            <!-- <geom type="mesh" rgba="0.792157 0.819608 0.933333 1" mesh="right_shoulder_pitch_link"/> -->
            <geom size="0.02 0.015" pos="0 -0.055 0" quat="0.707282 0 0.706931 0" type="cylinder" rgba="0.792157 0.819608 0.933333 1"/>
            <body name="right_shoulder_roll_link" pos="0.03575 -0.050671 -0.008" quat="0.996195 0.0871543 0 0">
              <inertial pos="-0.0236679 -0.00401309 -0.0303704" quat="0.692669 0.172206 0.262899 0.649183" mass="0.21" diaginertia="0.00034669 0.000332885 0.000199164"/>
              <joint name="right_shoulder_roll_joint" pos="0 0 0" axis="1 0 0" range="-2.25147 0.0872665"/>
              <geom type="mesh" contype="0" conaffinity="0" group="1" density="0" rgba="0.890196 0.890196 0.913725 1" mesh="right_shoulder_roll_link"/>
              <!-- <geom type="mesh" rgba="0.890196 0.890196 0.913725 1" mesh="right_shoulder_roll_link"/> -->
              <body name="right_shoulder_yaw_link" pos="-0.03575 -0.005 -0.0575">
                <inertial pos="-0.00514781 0.00182269 -0.0983288" quat="0.959408 0.0378083 -0.0557529 -0.273857" mass="1.334" diaginertia="0.00407972 0.00399458 0.00107571"/>
                <joint name="right_shoulder_yaw_joint" pos="0 0 0" axis="0 0 1" range="-2.61799 2.61799"/>
                <geom type="mesh" contype="0" conaffinity="0" group="1" density="0" rgba="0.792157 0.819608 0.933333 1" mesh="right_shoulder_yaw_link"/>
                <geom size="0.005 0.05" pos="0 -0.02 -0.1" type="cylinder" rgba="0.792157 0.819608 0.933333 1"/>
                <body name="right_arm_pitch_link" pos="0.015711 -0.03172 -0.144">
                  <inertial pos="0.0532646 0.0158532 -0.01447" quat="-0.155088 0.785577 0.0728078 0.594572" mass="0.656" diaginertia="0.00109587 0.0010614 0.000550548"/>
                  <joint name="right_arm_pitch_joint" pos="0 0 0" axis="0 1 0" range="-0.959931 2.0944"/>
                  <geom type="mesh" contype="0" conaffinity="0" group="1" density="0" rgba="0.698039 0.698039 0.698039 1" mesh="right_arm_pitch_link"/>
                  <!-- <geom type="mesh" rgba="0.698039 0.698039 0.698039 1" mesh="right_arm_pitch_link"/> -->
                  <geom size="0.03 0.025" pos="0.07 0.03 -0.015" quat="0.707282 0 -0.706931 0" type="cylinder" rgba="0.698039 0.698039 0.698039 1"/>
                  <body name="right_arm_yaw_link" pos="0.111 0.03125 -0.018">
                    <inertial pos="0.0259387 0.0110741 -1.671e-05" quat="-0.227905 0.669679 0.2252 0.669981" mass="0.14" diaginertia="0.00022854 0.000216321 0.000131368"/>
                    <joint name="right_arm_yaw_joint" pos="0 0 0" axis="1 0 0" range="-1.97222 1.97222"/>
                    <geom type="mesh" contype="0" conaffinity="0" group="1" density="0" rgba="0.890196 0.890196 0.913725 1" mesh="right_arm_yaw_link"/>
                    <geom type="mesh" rgba="0.890196 0.890196 0.913725 1" mesh="right_arm_yaw_link"/>
                    <body name="right_hand_pitch_link" pos="0.051 0.03175 0">
                      <inertial pos="0.0388116 -0.0305894 -0.00274471" quat="0.473258 0.549032 0.518518 0.453575" mass="0.94" diaginertia="0.00142238 0.00137869 0.000758634"/>
                      <joint name="right_hand_pitch_joint" pos="0 0 0" axis="0 1 0" range="-1.0472 1.0472"/>
                      <geom type="mesh" contype="0" conaffinity="0" group="1" density="0" rgba="0.792157 0.819608 0.933333 1" mesh="right_hand_pitch_link"/>
                      <geom type="mesh" rgba="0.792157 0.819608 0.933333 1" mesh="right_hand_pitch_link"/>
                      <body name="right_hand_roll_link" pos="0.068 -0.03175 0.03175">
                        <inertial pos="0.0951687 -1.6e-06 -0.0300965" quat="0.468409 0.529661 0.529786 0.46838" mass="0.125" diaginertia="0.000910631 0.000865381 0.000216191"/>
                        <joint name="right_hand_roll_joint" pos="0 0 0" axis="0 0 1" range="-1.0472 1.0472"/>
                        <geom type="mesh" contype="0" conaffinity="0" group="1" density="0" rgba="0.698039 0.698039 0.698039 1" mesh="right_hand_roll_link"/>
                        <geom type="mesh" rgba="0.698039 0.698039 0.698039 1" mesh="right_hand_roll_link"/>
                        <geom size="5e-07 5e-07 5e-07" pos="0.0735 0 -0.03175" quat="0.499998 0.5 0.500002 0.5" type="box" contype="0" conaffinity="0" group="1" density="0" rgba="0.698039 0.698039 0.698039 1"/>
                        <geom size="5e-07 5e-07 5e-07" pos="0.0735 0 -0.03175" quat="0.499998 0.5 0.500002 0.5" type="box" rgba="0.698039 0.698039 0.698039 1"/>
                      </body>
                    </body>
                  </body>
                </body>
              </body>
            </body>
          </body>
          <body name="head_yaw_link" pos="0 0 0.596">
            <inertial pos="0 0.00856423 -0.0573692" quat="0.998016 -0.0629548 0 0" mass="0.365" diaginertia="0.00155262 0.00152312 8.46154e-05"/>
            <joint name="head_yaw_joint" pos="0 0 0" axis="0 0 1" range="-1.0472 1.0472"/>
            <geom type="mesh" contype="0" conaffinity="0" group="1" density="0" rgba="0.698039 0.698039 0.698039 1" mesh="head_yaw_link"/>
            <geom type="mesh" rgba="0.698039 0.698039 0.698039 1" mesh="head_yaw_link"/>
            <body name="head_pitch_link">
              <inertial pos="0.00272068 0.00121888 0.0567032" quat="-0.0711792 0.877778 -0.144138 0.451291" mass="1.088" diaginertia="0.00403403 0.00400585 0.00332123"/>
              <joint name="head_pitch_joint" pos="0 0 0" axis="0 1 0" range="-0.698132 0.261799"/>
              <geom type="mesh" contype="0" conaffinity="0" group="1" density="0" rgba="0.698039 0.698039 0.698039 1" mesh="head_pitch_link"/>
              <!-- <geom type="mesh" rgba="0.698039 0.698039 0.698039 1" mesh="head_pitch_link"/> -->
            </body>
          </body>
        </body>
      </body>
    </body>
  </worldbody>
  <actuator>
    <motor name="left_hip_pitch_joint" joint="left_hip_pitch_joint" gear="1" ctrllimited="true" ctrlrange="-150 150"/>
    <motor name="left_hip_roll_joint" joint="left_hip_roll_joint" gear="1" ctrllimited="true" ctrlrange="-130 130"/>
    <motor name="left_hip_yaw_joint" joint="left_hip_yaw_joint" gear="1" ctrllimited="true" ctrlrange="-130 130"/>
    <motor name="left_knee_joint" joint="left_knee_joint" gear="1" ctrllimited="true" ctrlrange="-150 150"/>
    <motor name="left_ankle_pitch_joint" joint="left_ankle_pitch_joint" gear="1" ctrllimited="true" ctrlrange="-75 75"/>
    <motor name="left_ankle_roll_joint" joint="left_ankle_roll_joint" gear="1" ctrllimited="true" ctrlrange="-75 75"/>

    <motor name="right_hip_pitch_joint" joint="right_hip_pitch_joint" gear="1" ctrllimited="true" ctrlrange="-150 150"/>
    <motor name="right_hip_roll_joint" joint="right_hip_roll_joint" gear="1" ctrllimited="true" ctrlrange="-130 130"/>
    <motor name="right_hip_yaw_joint" joint="right_hip_yaw_joint" gear="1" ctrllimited="true" ctrlrange="-130 130"/>
    <motor name="right_knee_joint" joint="right_knee_joint" gear="1" ctrllimited="true" ctrlrange="-150 150"/>
    <motor name="right_ankle_pitch_joint" joint="right_ankle_pitch_joint" gear="1" ctrllimited="true" ctrlrange="-75 75"/>
    <motor name="right_ankle_roll_joint" joint="right_ankle_roll_joint" gear="1" ctrllimited="true" ctrlrange="-75 75"/>

    <motor name="waist_yaw_joint" joint="waist_yaw_joint" gear="1" ctrllimited="true" ctrlrange="-130 130"/>
    <motor name="waist_pitch_joint" joint="waist_pitch_joint" gear="1" ctrllimited="true" ctrlrange="-130 130"/>

    <motor name="left_shoulder_pitch_joint" joint="left_shoulder_pitch_joint" gear="1" ctrllimited="true" ctrlrange="-75 75"/>
    <motor name="left_shoulder_roll_joint" joint="left_shoulder_roll_joint" gear="1" ctrllimited="true" ctrlrange="-75 75"/>
    <motor name="left_shoulder_yaw_joint" joint="left_shoulder_yaw_joint" gear="1" ctrllimited="true" ctrlrange="-75 75"/>
    <motor name="left_arm_pitch_joint" joint="left_arm_pitch_joint" gear="1" ctrllimited="true" ctrlrange="-36 36"/>
    <motor name="left_arm_yaw_joint" joint="left_arm_yaw_joint" gear="1" ctrllimited="true" ctrlrange="-36 36"/>
    <motor name="left_hand_pitch_joint" joint="left_hand_pitch_joint" gear="1" ctrllimited="true" ctrlrange="-36 36"/>
    <motor name="left_hand_roll_joint" joint="left_hand_roll_joint" gear="1" ctrllimited="true" ctrlrange="-36 36"/>

    <motor name="right_shoulder_pitch_joint" joint="right_shoulder_pitch_joint" gear="1" ctrllimited="true" ctrlrange="-75 75"/>
    <motor name="right_shoulder_roll_joint" joint="right_shoulder_roll_joint" gear="1" ctrllimited="true" ctrlrange="-75 75"/>
    <motor name="right_shoulder_yaw_joint" joint="right_shoulder_yaw_joint" gear="1" ctrllimited="true" ctrlrange="-75 75"/>
    <motor name="right_arm_pitch_joint" joint="right_arm_pitch_joint" gear="1" ctrllimited="true" ctrlrange="-36 36"/>
    <motor name="right_arm_yaw_joint" joint="right_arm_yaw_joint" gear="1" ctrllimited="true" ctrlrange="-36 36"/>
    <motor name="right_hand_pitch_joint" joint="right_hand_pitch_joint" gear="1" ctrllimited="true" ctrlrange="-36 36"/>
    <motor name="right_hand_roll_joint" joint="right_hand_roll_joint" gear="1" ctrllimited="true" ctrlrange="-36 36"/>

    <motor name="head_yaw_joint" joint="head_yaw_joint" gear="1" ctrllimited="true" ctrlrange="-12 12"/>
    <motor name="head_pitch_joint" joint="head_pitch_joint" gear="1" ctrllimited="true" ctrlrange="-12 12"/>

  </actuator>

  <sensor>
    <framequat name='orientation' objtype='site' noise='0.001' objname='imu_in_base'/>
    <framepos name='position' objtype='site' noise='0.001' objname='imu_in_base'/>
    <gyro name='angular-velocity' site='imu_in_base' noise='0.005' cutoff='34.9'/>
    <velocimeter name='linear-velocity' site='imu_in_base' noise='0.001' cutoff='30'/>
    <accelerometer name='linear-acceleration' site='imu_in_base' noise='0.005' cutoff='157'/>
    <magnetometer name='magnetometer' site='imu_in_base'/>
  </sensor>

</mujoco>
